Workbook

Sheet Readme
H5: FP&A / Strategic Finance Platform
D6: Template SaaS Financial Model
D7: Get started! This B2B SaaS financial model template helps you forecast your company's future performance using a connected driver-based model. The template is intended as a starting point for SaaS companies to model revenues and project their financial performance. We understand no two businesses are the same, and you can modify it as needed to suit the needs of your business. The key components of this SaaS financial model include: • Assumptions • Actuals sheet (to record your historical data) • ARR Summary • Customer Summary • Average Contract Value Summary • Churn Metrics • SaaS Metrics • Income Statement (P&L) • Customer Control • Dashboard
D10: Cell value type | F10: Description
D12: Input (Actuals or Assumptions) | F12: Manually input your actuals data or assumption values in these cells shaded in light yellow. Note: These cells have been pre-populated with sample data
D13: Formula | F13: These cells are automatically calculated using a formula. You can edit the formula to suit your needs

Sheet Key Assumptions
A2: Assumptions SaaS Financial Model
C4: Notes
C5: 1. Enter the start and end dates for the period you have historical data. Feel free to enter the data for whatever time period is available
C6: 2. The forecast period starts 1-day post the end of the historical period specified. The forecast period is set to 36 months
C7: 3. Enter your assumptions for pipeline, expansion and income statement metrics
C8: 4. Rows 19-22 (hidden) contain flags for indicating historical or forecast columns and the year column (for annual roll-ups). Toggle these to "1" for rolling your forecasts over time. This applies to all sheets.
C12: Model Timeline | G12: Format type | I12: =IF(I20=1,"Actual","Forecast") -> Actual | J12: =IF(J20=1,"Actual","Forecast") -> Actual | K12: =IF(K20=1,"Actual","Forecast") -> Forecast | L12: =IF(L20=1,"Actual","Forecast") -> Forecast | M12: =IF(M20=1,"Actual","Forecast") -> Forecast | O12: =IF(O20=1,"Actual","Forecast") -> Actual | P12: =IF(P20=1,"Actual","Forecast") -> Actual | Q12: =IF(Q20=1,"Actual","Forecast") -> Actual | R12: =IF(R20=1,"Actual","Forecast") -> Actual | S12: =IF(S20=1,"Actual","Forecast") -> Actual | T12: =IF(T20=1,"Actual","Forecast") -> Actual | U12: =IF(U20=1,"Actual","Forecast") -> Actual | V12: =IF(V20=1,"Actual","Forecast") -> Actual | ... BV12: =IF(BV20=1,"Actual","Forecast") -> Forecast
C13: Start of Historical Period | D13: 44562 | H13: Date | I13: =I14 -> 44562 | J13: =J14 -> 44927 | K13: =K14 -> 45292 | L13: =L14 -> 45658 | M13: =M14 -> 46023 | O13: =O14 -> 44562 | P13: =P14 -> 44593 | Q13: =Q14 -> 44621 | R13: =R14 -> 44652 | S13: =S14 -> 44682 | T13: =T14 -> 44713 | U13: =U14 -> 44743 | V13: =V14 -> 44774 | ... BV13: =BV14 -> 46357
C14: End of Historical Period | D14: 45107 | H14: Start of Period | I14: ='Key Assumptions'!D13 -> 44562 | J14: =I15+1 -> 44927 | K14: =J15+1 -> 45292 | L14: =K15+1 -> 45658 | M14: =L15+1 -> 46023 | O14: ='Key Assumptions'!D13 -> 44562 | P14: =O15+1 -> 44593 | Q14: =P15+1 -> 44621 | R14: =Q15+1 -> 44652 | S14: =R15+1 -> 44682 | T14: =S15+1 -> 44713 | U14: =T15+1 -> 44743 | V14: =U15+1 -> 44774 | W14: =V15+1 -> 44805 | ... BV14: =BU15+1 -> 46357
C15: Start of Forecast Period | D15: =D14+1 -> 45108 | H15: End of Period | I15: =EOMONTH(I14,11) -> 44926 | J15: =EOMONTH(J14,11) -> 45291 | K15: =EOMONTH(K14,11) -> 45657 | L15: =EOMONTH(L14,11) -> 46022 | M15: =EOMONTH(M14,11) -> 46387 | O15: =EOMONTH(O14,0) -> 44592 | P15: =EOMONTH(P14,0) -> 44620 | Q15: =EOMONTH(Q14,0) -> 44651 | R15: =EOMONTH(R14,0) -> 44681 | S15: =EOMONTH(S14,0) -> 44712 | T15: =EOMONTH(T14,0) -> 44742 | U15: =EOMONTH(U14,0) -> 44773 | V15: =EOMONTH(V14,0) -> 44804 | ... BV15: =EOMONTH(BV14,0) -> 46387
C16: End of Forecast Period | D16: =EOMONTH(D13,59) -> 46387 | H16: Timeline | I16: =IF(I15-I14>35,"Annual","Monthly") -> Annual | J16: =IF(J15-J14>35,"Annual","Monthly") -> Annual | K16: =IF(K15-K14>35,"Annual","Monthly") -> Annual | L16: =IF(L15-L14>35,"Annual","Monthly") -> Annual | M16: =IF(M15-M14>35,"Annual","Monthly") -> Annual | O16: =IF(O15-O14>35,"Annual","Monthly") -> Monthly | P16: =IF(P15-P14>35,"Annual","Monthly") -> Monthly | Q16: =IF(Q15-Q14>35,"Annual","Monthly") -> Monthly | R16: =IF(R15-R14>35,"Annual","Monthly") -> Monthly | S16: =IF(S15-S14>35,"Annual","Monthly") -> Monthly | T16: =IF(T15-T14>35,"Annual","Monthly") -> Monthly | U16: =IF(U15-U14>35,"Annual","Monthly") -> Monthly | V16: =IF(V15-V14>35,"Annual","Monthly") -> Monthly | ... BV16: =IF(BV15-BV14>35,"Annual","Monthly") -> Monthly
H17: Year | I17: =YEAR(I14) -> 2022 | J17: =YEAR(J14) -> 2023 | K17: =YEAR(K14) -> 2024 | L17: =YEAR(L14) -> 2025 | M17: =YEAR(M14) -> 2026 | O17: =YEAR(O14) -> 2022 | P17: =YEAR(P14) -> 2022 | Q17: =YEAR(Q14) -> 2022 | R17: =YEAR(R14) -> 2022 | S17: =YEAR(S14) -> 2022 | T17: =YEAR(T14) -> 2022 | U17: =YEAR(U14) -> 2022 | V17: =YEAR(V14) -> 2022 | ... BV17: =YEAR(BV14) -> 2026
H19: Flag
H20: Historical Flag | I20: =IF(AND(I14>='Key Assumptions'!$D$13,I14<'Key Assumptions'!$D$14),1,0) -> 1 | J20: =IF(AND(J14>='Key Assumptions'!$D$13,J14<'Key Assumptions'!$D$14),1,0) -> 1 | K20: =IF(AND(K14>='Key Assumptions'!$D$13,K14<'Key Assumptions'!$D$14),1,0) -> 0 | L20: =IF(AND(L14>='Key Assumptions'!$D$13,L14<'Key Assumptions'!$D$14),1,0) -> 0 | M20: =IF(AND(M14>='Key Assumptions'!$D$13,M14<'Key Assumptions'!$D$14),1,0) -> 0 | O20: =IF(AND(O14>='Key Assumptions'!$D$13,O14<'Key Assumptions'!$D$14),1,0) -> 1 | P20: =IF(AND(P14>='Key Assumptions'!$D$13,P14<'Key Assumptions'!$D$14),1,0) -> 1 | Q20: =IF(AND(Q14>='Key Assumptions'!$D$13,Q14<'Key Assumptions'!$D$14),1,0) -> 1 | R20: =IF(AND(R14>='Key Assumptions'!$D$13,R14<'Key Assumptions'!$D$14),1,0) -> 1 | S20: =IF(AND(S14>='Key Assumptions'!$D$13,S14<'Key Assumptions'!$D$14),1,0) -> 1 | T20: =IF(AND(T14>='Key Assumptions'!$D$13,T14<'Key Assumptions'!$D$14),1,0) -> 1 | U20: =IF(AND(U14>='Key Assumptions'!$D$13,U14<'Key Assumptions'!$D$14),1,0) -> 1 | V20: =IF(AND(V14>='Key Assumptions'!$D$13,V14<'Key Assumptions'!$D$14),1,0) -> 1 | ... BV20: =IF(AND(BV14>='Key Assumptions'!$D$13,BV14<'Key Assumptions'!$D$14),1,0) -> 0
H21: Forecast Flag | I21: =IF(AND(I14>='Key Assumptions'!$D$15,I14<'Key Assumptions'!$D$16),1,0) -> 0 | J21: =IF(AND(J14>='Key Assumptions'!$D$15,J14<'Key Assumptions'!$D$16),1,0) -> 0 | K21: =IF(AND(K14>='Key Assumptions'!$D$15,K14<'Key Assumptions'!$D$16),1,0) -> 1 | L21: =IF(AND(L14>='Key Assumptions'!$D$15,L14<'Key Assumptions'!$D$16),1,0) -> 1 | M21: =IF(AND(M14>='Key Assumptions'!$D$15,M14<'Key Assumptions'!$D$16),1,0) -> 1 | O21: =IF(AND(O14>='Key Assumptions'!$D$15,O14<'Key Assumptions'!$D$16),1,0) -> 0 | P21: =IF(AND(P14>='Key Assumptions'!$D$15,P14<'Key Assumptions'!$D$16),1,0) -> 0 | Q21: =IF(AND(Q14>='Key Assumptions'!$D$15,Q14<'Key Assumptions'!$D$16),1,0) -> 0 | R21: =IF(AND(R14>='Key Assumptions'!$D$15,R14<'Key Assumptions'!$D$16),1,0) -> 0 | S21: =IF(AND(S14>='Key Assumptions'!$D$15,S14<'Key Assumptions'!$D$16),1,0) -> 0 | T21: =IF(AND(T14>='Key Assumptions'!$D$15,T14<'Key Assumptions'!$D$16),1,0) -> 0 | U21: =IF(AND(U14>='Key Assumptions'!$D$15,U14<'Key Assumptions'!$D$16),1,0) -> 0 | V21: =IF(AND(V14>='Key Assumptions'!$D$15,V14<'Key Assumptions'!$D$16),1,0) -> 0 | ... BV21: =IF(AND(BV14>='Key Assumptions'!$D$15,BV14<'Key Assumptions'!$D$16),1,0) -> 1
H22: Year Flag | I22: =COUNTA($I$14:I14) -> 1 | J22: =COUNTA($I$14:J14) -> 2 | K22: =COUNTA($I$14:K14) -> 3 | L22: =COUNTA($I$14:L14) -> 4 | M22: =COUNTA($I$14:M14) -> 5 | O22: =INDEX($I$22:$M$22,MATCH(YEAR(O$14),$I$17:$M$17,0)) -> 1 | P22: =INDEX($I$22:$M$22,MATCH(YEAR(P$14),$I$17:$M$17,0)) -> 1 | Q22: =INDEX($I$22:$M$22,MATCH(YEAR(Q$14),$I$17:$M$17,0)) -> 1 | R22: =INDEX($I$22:$M$22,MATCH(YEAR(R$14),$I$17:$M$17,0)) -> 1 | S22: =INDEX($I$22:$M$22,MATCH(YEAR(S$14),$I$17:$M$17,0)) -> 1 | T22: =INDEX($I$22:$M$22,MATCH(YEAR(T$14),$I$17:$M$17,0)) -> 1 | U22: =INDEX($I$22:$M$22,MATCH(YEAR(U$14),$I$17:$M$17,0)) -> 1 | V22: =INDEX($I$22:$M$22,MATCH(YEAR(V$14),$I$17:$M$17,0)) -> 1 | ... BV22: =INDEX($I$22:$M$22,MATCH(YEAR(BV$14),$I$17:$M$17,0)) -> 5
C25: Pipeline assumptions
C26: Leads per month | G26: # | I26: =SUMIFS($O26:$BV26,$O$22:$BV$22,I$22) -> 6000 | J26: =SUMIFS($O26:$BV26,$O$22:$BV$22,J$22) -> 6000 | K26: =SUMIFS($O26:$BV26,$O$22:$BV$22,K$22) -> 6000 | L26: =SUMIFS($O26:$BV26,$O$22:$BV$22,L$22) -> 6000 | M26: =SUMIFS($O26:$BV26,$O$22:$BV$22,M$22) -> 6000 | O26: 500 | P26: 500 | Q26: 500 | R26: 500 | S26: 500 | T26: 500 | U26: 500 | V26: 500 | W26: 500 | X26: 500 | Y26: 500 | Z26: 500 | AA26: 500 | AB26: 500 | AC26: 500 | AD26: 500 | AE26: 500 | AF26: 500 | AG26: 500 | AH26: 500 | AI26: 500 | AJ26: 500 | AK26: 500 | AL26: 500 | AM26: 500 | AN26: 500 | AO26: 500 | AP26: 500 | AQ26: 500 | AR26: 500 | AS26: 500 | AT26: 500 | AU26: 500 | AV26: 500 | AW26: 500 | AX26: 500 | AY26: 500 | AZ26: 500 | BA26: 500 | BB26: 500 | BC26: 500 | BD26: 500 | BE26: 500 | BF26: 500 | BG26: 500 | BH26: 500 | BI26: 500 | BJ26: 500 | BK26: 500 | BL26: 500 | BM26: 500 | BN26: 500 | BO26: 500 | BP26: 500 | BQ26: 500 | BR26: 500 | BS26: 500 | BT26: 500 | BU26: 500 | BV26: 500
C28: Expansion Assumption
C29: Expansion | G29: # | I29: =SUMIFS($O29:$BV29,$O$22:$BV$22,I$22) -> 2329537.4 | J29: =SUMIFS($O29:$BV29,$O$22:$BV$22,J$22) -> 2335236.3 | K29: =SUMIFS($O29:$BV29,$O$22:$BV$22,K$22) -> 2346644.4 | L29: =SUMIFS($O29:$BV29,$O$22:$BV$22,L$22) -> 2347249.8 | M29: =SUMIFS($O29:$BV29,$O$22:$BV$22,M$22) -> 2347245.1 | O29: 178762.11 | P29: 173603.52 | Q29: 233465.2 | R29: 200328.63 | S29: 149405.29 | T29: 233644.93 | U29: 252277.53 | V29: 223411.45 | W29: 152917.62 | X29: 249669.6 | Y29: 151168.28 | Z29: 130883.26 | AA29: 189577.97 | AB29: 224186.78 | AC29: 136883.26 | AD29: 202167.4 | AE29: 220599.12 | AF29: 191235.24 | AG29: 194108.3 | AH29: 194863.35 | AI29: 189976.11 | AJ29: 198824.92 | AK29: 198267.84 | AL29: 194545.96 | AM29: 195097.75 | AN29: 195262.65 | AO29: 195329.21 | AP29: 196221.39 | AQ29: 195787.47 | AR29: 195374.07 | AS29: 195512.09 | AT29: 195581.15 | AU29: 195634.23 | AV29: 195685.06 | AW29: 195595.68 | AX29: 195563.71 | AY29: 195595.32 | AZ29: 195609.19 | BA29: 195613.86 | BB29: 195610.47 | BC29: 195598.04 | BD29: 195598.43 | BE29: 195604.22 | BF29: 195605.7 | BG29: 195605.12 | BH29: 195603.66 | BI29: 195602.53 | BJ29: 195603.28 | BK29: 195604.09 | BL29: 195604.06 | BM29: 195603.79 | BN29: 195603.57 | BO29: 195603.55 | BP29: 195603.72 | BQ29: 195603.8 | BR29: 195603.75 | BS29: 195603.7 | BT29: 195603.68 | BU29: 195603.7 | BV29: 195603.73
C31: Income statement assumptions
C32: Gross Margin | G32: % | I32: =iferror(AVERAGEIFS($O32:$BJ32,$O$22:$BJ$22,I$22),0) -> 0.8 | J32: =iferror(AVERAGEIFS($O32:$BJ32,$O$22:$BJ$22,J$22),0) -> 0.8 | K32: =iferror(AVERAGEIFS($O32:$BJ32,$O$22:$BJ$22,K$22),0) -> 0.8 | L32: =iferror(AVERAGEIFS($O32:$BJ32,$O$22:$BJ$22,L$22),0) -> 0.8 | M32: =iferror(AVERAGEIFS($O32:$BJ32,$O$22:$BJ$22,M$22),0) -> 0 | O32: 0.8 | P32: 0.8 | Q32: 0.8 | R32: 0.8 | S32: 0.8 | T32: 0.8 | U32: 0.8 | V32: 0.8 | W32: 0.8 | X32: 0.8 | Y32: 0.8 | Z32: 0.8 | AA32: 0.8 | AB32: 0.8 | AC32: 0.8 | AD32: 0.8 | AE32: 0.8 | AF32: 0.8 | AG32: 0.8 | AH32: 0.8 | AI32: 0.8 | AJ32: 0.8 | AK32: 0.8 | AL32: 0.8 | AM32: 0.8 | AN32: 0.8 | AO32: 0.8 | AP32: 0.8 | AQ32: 0.8 | AR32: 0.8 | AS32: 0.8 | AT32: 0.8 | AU32: 0.8 | AV32: 0.8 | AW32: 0.8 | AX32: 0.8 | AY32: 0.8 | AZ32: 0.8 | BA32: 0.8 | BB32: 0.8 | BC32: 0.8 | BD32: 0.8 | BE32: 0.8 | BF32: 0.8 | BG32: 0.8 | BH32: 0.8 | BI32: 0.8 | BJ32: 0.8 | BK32: 0.8 | BL32: 0.8 | BM32: 0.8 | BN32: 0.8 | BO32: 0.8 | BP32: 0.8 | BQ32: 0.8 | BR32: 0.8 | BS32: 0.8 | BT32: 0.8 | BU32: 0.8 | BV32: 0.8
C33: G&A | G33: $'000s | I33: =SUMIFS($O33:$BV33,$O$22:$BV$22,I$22) -> 3016.5551 | J33: =SUMIFS($O33:$BV33,$O$22:$BV$22,J$22) -> 3052.9535 | K33: =SUMIFS($O33:$BV33,$O$22:$BV$22,K$22) -> 3089.7912 | L33: =SUMIFS($O33:$BV33,$O$22:$BV$22,L$22) -> 3127.0733 | M33: =SUMIFS($O33:$BV33,$O$22:$BV$22,M$22) -> 3164.8052 | O33: =Actuals!N62 -> 250 | P33: =O33*1.001 -> 250.25 | Q33: =P33*1.001 -> 250.50025 | R33: =Q33*1.001 -> 250.75075 | S33: =R33*1.001 -> 251.0015 | T33: =S33*1.001 -> 251.2525 | U33: =T33*1.001 -> 251.50376 | V33: =U33*1.001 -> 251.75526 | W33: =V33*1.001 -> 252.00701 | ... BV33: =BU33*1.001 -> 265.18599
C34: S&M | G34: $'000s | I34: =SUMIFS($O34:$BV34,$O$22:$BV$22,I$22) -> 7239.7323 | J34: =SUMIFS($O34:$BV34,$O$22:$BV$22,J$22) -> 7327.0885 | K34: =SUMIFS($O34:$BV34,$O$22:$BV$22,K$22) -> 7415.4988 | L34: =SUMIFS($O34:$BV34,$O$22:$BV$22,L$22) -> 7504.9758 | M34: =SUMIFS($O34:$BV34,$O$22:$BV$22,M$22) -> 7595.5325 | O34: =Actuals!N63 -> 600 | P34: =O34*1.001 -> 600.6 | Q34: =P34*1.001 -> 601.2006 | R34: =Q34*1.001 -> 601.8018 | S34: =R34*1.001 -> 602.4036 | T34: =S34*1.001 -> 603.00601 | U34: =T34*1.001 -> 603.60901 | V34: =U34*1.001 -> 604.21262 | W34: =V34*1.001 -> 604.81683 | ... BV34: =BU34*1.001 -> 636.44638
C35: R&D | G35: $'000s | I35: =SUMIFS($O35:$BV35,$O$22:$BV$22,I$22) -> 4826.4882 | J35: =SUMIFS($O35:$BV35,$O$22:$BV$22,J$22) -> 4884.7257 | K35: =SUMIFS($O35:$BV35,$O$22:$BV$22,K$22) -> 4943.6658 | L35: =SUMIFS($O35:$BV35,$O$22:$BV$22,L$22) -> 5003.3172 | M35: =SUMIFS($O35:$BV35,$O$22:$BV$22,M$22) -> 5063.6883 | O35: =Actuals!N64 -> 400 | P35: =O35*1.001 -> 400.4 | Q35: =P35*1.001 -> 400.8004 | R35: =Q35*1.001 -> 401.2012 | S35: =R35*1.001 -> 401.6024 | T35: =S35*1.001 -> 402.004 | U35: =T35*1.001 -> 402.40601 | V35: =U35*1.001 -> 402.80841 | W35: =V35*1.001 -> 403.21122 | ... BV35: =BU35*1.001 -> 424.29759

Sheet Actuals
C2: Actuals SaaS Financial Model
C4: Notes
C5: 1. Enter your actuals in this sheet
C6: 2. Note for cohort metrics such as GRR and NRR, calculate the values as per the steps mentioned in this article and input the actuals here
H9: =IF(H17=1,"Actual","Forecast") -> Actual | I9: =IF(I17=1,"Actual","Forecast") -> Actual | J9: =IF(J17=1,"Actual","Forecast") -> Forecast | K9: =IF(K17=1,"Actual","Forecast") -> Forecast | L9: =IF(L17=1,"Actual","Forecast") -> Forecast | N9: =IF(N17=1,"Actual","Forecast") -> Actual | O9: =IF(O17=1,"Actual","Forecast") -> Actual | P9: =IF(P17=1,"Actual","Forecast") -> Actual | Q9: =IF(Q17=1,"Actual","Forecast") -> Actual | R9: =IF(R17=1,"Actual","Forecast") -> Actual | S9: =IF(S17=1,"Actual","Forecast") -> Actual | T9: =IF(T17=1,"Actual","Forecast") -> Actual | U9: =IF(U17=1,"Actual","Forecast") -> Actual | ... BU9: =IF(BU17=1,"Actual","Forecast") -> Forecast
H10: =H11 -> 44562 | I10: =I11 -> 44927 | J10: =J11 -> 45292 | K10: =K11 -> 45658 | L10: =L11 -> 46023 | N10: =N11 -> 44562 | O10: =O11 -> 44593 | P10: =P11 -> 44621 | Q10: =Q11 -> 44652 | R10: =R11 -> 44682 | S10: =S11 -> 44713 | T10: =T11 -> 44743 | U10: =U11 -> 44774 | ... BU10: =BU11 -> 46357
G11: Start of Period | H11: ='Key Assumptions'!D13 -> 44562 | I11: =H12+1 -> 44927 | J11: =I12+1 -> 45292 | K11: =J12+1 -> 45658 | L11: =K12+1 -> 46023 | N11: ='Key Assumptions'!D13 -> 44562 | O11: =N12+1 -> 44593 | P11: =O12+1 -> 44621 | Q11: =P12+1 -> 44652 | R11: =Q12+1 -> 44682 | S11: =R12+1 -> 44713 | T11: =S12+1 -> 44743 | U11: =T12+1 -> 44774 | V11: =U12+1 -> 44805 | ... BU11: =BT12+1 -> 46357
G12: End of Period | H12: =EOMONTH(H11,11) -> 44926 | I12: =EOMONTH(I11,11) -> 45291 | J12: =EOMONTH(J11,11) -> 45657 | K12: =EOMONTH(K11,11) -> 46022 | L12: =EOMONTH(L11,11) -> 46387 | N12: =EOMONTH(N11,0) -> 44592 | O12: =EOMONTH(O11,0) -> 44620 | P12: =EOMONTH(P11,0) -> 44651 | Q12: =EOMONTH(Q11,0) -> 44681 | R12: =EOMONTH(R11,0) -> 44712 | S12: =EOMONTH(S11,0) -> 44742 | T12: =EOMONTH(T11,0) -> 44773 | U12: =EOMONTH(U11,0) -> 44804 | ... BU12: =EOMONTH(BU11,0) -> 46387
G13: Timeline | H13: =IF(H12-H11>35,"Annual","Monthly") -> Annual | I13: =IF(I12-I11>35,"Annual","Monthly") -> Annual | J13: =IF(J12-J11>35,"Annual","Monthly") -> Annual | K13: =IF(K12-K11>35,"Annual","Monthly") -> Annual | L13: =IF(L12-L11>35,"Annual","Monthly") -> Annual | N13: =IF(N12-N11>35,"Annual","Monthly") -> Monthly | O13: =IF(O12-O11>35,"Annual","Monthly") -> Monthly | P13: =IF(P12-P11>35,"Annual","Monthly") -> Monthly | Q13: =IF(Q12-Q11>35,"Annual","Monthly") -> Monthly | R13: =IF(R12-R11>35,"Annual","Monthly") -> Monthly | S13: =IF(S12-S11>35,"Annual","Monthly") -> Monthly | T13: =IF(T12-T11>35,"Annual","Monthly") -> Monthly | U13: =IF(U12-U11>35,"Annual","Monthly") -> Monthly | ... BU13: =IF(BU12-BU11>35,"Annual","Monthly") -> Monthly
G14: Year | H14: =YEAR(H11) -> 2022 | I14: =YEAR(I11) -> 2023 | J14: =YEAR(J11) -> 2024 | K14: =YEAR(K11) -> 2025 | L14: =YEAR(L11) -> 2026 | N14: =YEAR(N11) -> 2022 | O14: =YEAR(O11) -> 2022 | P14: =YEAR(P11) -> 2022 | Q14: =YEAR(Q11) -> 2022 | R14: =YEAR(R11) -> 2022 | S14: =YEAR(S11) -> 2022 | T14: =YEAR(T11) -> 2022 | U14: =YEAR(U11) -> 2022 | ... BU14: =YEAR(BU11) -> 2026
G16: Flag
G17: Historical Flag | H17: =IF(AND(H11>='Key Assumptions'!$D$13,H11<'Key Assumptions'!$D$14),1,0) -> 1 | I17: =IF(AND(I11>='Key Assumptions'!$D$13,I11<'Key Assumptions'!$D$14),1,0) -> 1 | J17: =IF(AND(J11>='Key Assumptions'!$D$13,J11<'Key Assumptions'!$D$14),1,0) -> 0 | K17: =IF(AND(K11>='Key Assumptions'!$D$13,K11<'Key Assumptions'!$D$14),1,0) -> 0 | L17: =IF(AND(L11>='Key Assumptions'!$D$13,L11<'Key Assumptions'!$D$14),1,0) -> 0 | N17: =IF(AND(N11>='Key Assumptions'!$D$13,N11<'Key Assumptions'!$D$14),1,0) -> 1 | O17: =IF(AND(O11>='Key Assumptions'!$D$13,O11<'Key Assumptions'!$D$14),1,0) -> 1 | P17: =IF(AND(P11>='Key Assumptions'!$D$13,P11<'Key Assumptions'!$D$14),1,0) -> 1 | Q17: =IF(AND(Q11>='Key Assumptions'!$D$13,Q11<'Key Assumptions'!$D$14),1,0) -> 1 | R17: =IF(AND(R11>='Key Assumptions'!$D$13,R11<'Key Assumptions'!$D$14),1,0) -> 1 | S17: =IF(AND(S11>='Key Assumptions'!$D$13,S11<'Key Assumptions'!$D$14),1,0) -> 1 | T17: =IF(AND(T11>='Key Assumptions'!$D$13,T11<'Key Assumptions'!$D$14),1,0) -> 1 | U17: =IF(AND(U11>='Key Assumptions'!$D$13,U11<'Key Assumptions'!$D$14),1,0) -> 1 | ... BU17: =IF(AND(BU11>='Key Assumptions'!$D$13,BU11<'Key Assumptions'!$D$14),1,0) -> 0
G18: Forecast Flag | H18: =IF(AND(H11>='Key Assumptions'!$D$15,H11<'Key Assumptions'!$D$16),1,0) -> 0 | I18: =IF(AND(I11>='Key Assumptions'!$D$15,I11<'Key Assumptions'!$D$16),1,0) -> 0 | J18: =IF(AND(J11>='Key Assumptions'!$D$15,J11<'Key Assumptions'!$D$16),1,0) -> 1 | K18: =IF(AND(K11>='Key Assumptions'!$D$15,K11<'Key Assumptions'!$D$16),1,0) -> 1 | L18: =IF(AND(L11>='Key Assumptions'!$D$15,L11<'Key Assumptions'!$D$16),1,0) -> 1 | N18: =IF(AND(N11>='Key Assumptions'!$D$15,N11<'Key Assumptions'!$D$16),1,0) -> 0 | O18: =IF(AND(O11>='Key Assumptions'!$D$15,O11<'Key Assumptions'!$D$16),1,0) -> 0 | P18: =IF(AND(P11>='Key Assumptions'!$D$15,P11<'Key Assumptions'!$D$16),1,0) -> 0 | Q18: =IF(AND(Q11>='Key Assumptions'!$D$15,Q11<'Key Assumptions'!$D$16),1,0) -> 0 | R18: =IF(AND(R11>='Key Assumptions'!$D$15,R11<'Key Assumptions'!$D$16),1,0) -> 0 | S18: =IF(AND(S11>='Key Assumptions'!$D$15,S11<'Key Assumptions'!$D$16),1,0) -> 0 | T18: =IF(AND(T11>='Key Assumptions'!$D$15,T11<'Key Assumptions'!$D$16),1,0) -> 0 | U18: =IF(AND(U11>='Key Assumptions'!$D$15,U11<'Key Assumptions'!$D$16),1,0) -> 0 | ... BU18: =IF(AND(BU11>='Key Assumptions'!$D$15,BU11<'Key Assumptions'!$D$16),1,0) -> 1
G19: Year Flag | H19: =COUNTA($H$11:H11) -> 1 | I19: =COUNTA($H$11:I11) -> 2 | J19: =COUNTA($H$11:J11) -> 3 | K19: =COUNTA($H$11:K11) -> 4 | L19: =COUNTA($H$11:L11) -> 5 | N19: =INDEX($H$19:$L$19,MATCH(YEAR(N$11),$H$14:$L$14,0)) -> 1 | O19: =INDEX($H$19:$L$19,MATCH(YEAR(O$11),$H$14:$L$14,0)) -> 1 | P19: =INDEX($H$19:$L$19,MATCH(YEAR(P$11),$H$14:$L$14,0)) -> 1 | Q19: =INDEX($H$19:$L$19,MATCH(YEAR(Q$11),$H$14:$L$14,0)) -> 1 | R19: =INDEX($H$19:$L$19,MATCH(YEAR(R$11),$H$14:$L$14,0)) -> 1 | S19: =INDEX($H$19:$L$19,MATCH(YEAR(S$11),$H$14:$L$14,0)) -> 1 | T19: =INDEX($H$19:$L$19,MATCH(YEAR(T$11),$H$14:$L$14,0)) -> 1 | U19: =INDEX($H$19:$L$19,MATCH(YEAR(U$11),$H$14:$L$14,0)) -> 1 | ... BU19: =INDEX($H$19:$L$19,MATCH(YEAR(BU$11),$H$14:$L$14,0)) -> 5
C21: ARR Summary
C22: Beginning ARR | G22: $ | H22: =INDEX($N22:$BU22,MATCH(H$11,$N$11:$BU$11,0)) -> 11935000 | I22: =INDEX($N22:$BU22,MATCH(I$11,$N$11:$BU$11,0)) -> 17099065 | J22: =INDEX($N22:$BU22,MATCH(J$11,$N$11:$BU$11,0)) | K22: =INDEX($N22:$BU22,MATCH(K$11,$N$11:$BU$11,0)) | L22: =INDEX($N22:$BU22,MATCH(L$11,$N$11:$BU$11,0)) | N22: 11935000 | O22: =N26 -> 12248800 | P22: =O26 -> 12691380 | Q22: =P26 -> 13205436 | R22: =Q26 -> 13595598 | S22: =R26 -> 13929304 | T22: =S26 -> 14504143 | U22: =T26 -> 15198474 | V22: =U26 -> 15699593 | ... AE22: =AD26 -> 19266078
C23: New ARR | G23: $ | H23: =SUMIFS($N23:$BU23,$N$19:$BU$19,H$19) -> 5288050 | I23: =SUMIFS($N23:$BU23,$N$19:$BU$19,I$19) -> 2643755 | J23: =SUMIFS($N23:$BU23,$N$19:$BU$19,J$19) -> 0 | K23: =SUMIFS($N23:$BU23,$N$19:$BU$19,K$19) -> 0 | L23: =SUMIFS($N23:$BU23,$N$19:$BU$19,L$19) -> 0 | N23: 405790 | O23: 394080 | P23: 529966 | Q23: 454746 | R23: 339150 | S23: 530374 | T23: 572670 | U23: 507144 | V23: 347123 | W23: 566750 | X23: 343152 | Y23: 297105 | Z23: 430342 | AA23: 508904 | AB23: 310725 | AC23: 458920 | AD23: 500760 | AE23: 434104
C24: Expansion ARR | G24: $ | H24: =SUMIFS($N24:$BU24,$N$19:$BU$19,H$19) -> 2329537.4 | I24: =SUMIFS($N24:$BU24,$N$19:$BU$19,I$19) -> 1164649.8 | J24: =SUMIFS($N24:$BU24,$N$19:$BU$19,J$19) -> 0 | K24: =SUMIFS($N24:$BU24,$N$19:$BU$19,K$19) -> 0 | L24: =SUMIFS($N24:$BU24,$N$19:$BU$19,L$19) -> 0 | N24: 178762.11 | O24: 173603.52 | P24: 233465.2 | Q24: 200328.63 | R24: 149405.29 | S24: 233644.93 | T24: 252277.53 | U24: 223411.45 | V24: 152917.62 | W24: 249669.6 | X24: 151168.28 | Y24: 130883.26 | Z24: 189577.97 | AA24: 224186.78 | AB24: 136883.26 | AC24: 202167.4 | AD24: 220599.12 | AE24: 191235.24
C25: Churn ARR | G25: $ | H25: =SUMIFS($N25:$BU25,$N$19:$BU$19,H$19) -> -2453522 | I25: =SUMIFS($N25:$BU25,$N$19:$BU$19,I$19) -> -1314525 | J25: =SUMIFS($N25:$BU25,$N$19:$BU$19,J$19) -> 0 | K25: =SUMIFS($N25:$BU25,$N$19:$BU$19,K$19) -> 0 | L25: =SUMIFS($N25:$BU25,$N$19:$BU$19,L$19) -> 0 | N25: -270752 | O25: -125104 | P25: -249375 | Q25: -264912 | R25: -154850 | S25: -189180 | T25: -130616 | U25: -229437 | V25: -201654 | W25: -252300 | X25: -252830 | Y25: -132512 | Z25: -107376 | AA25: -136936 | AB25: -202352 | AC25: -269773 | AD25: -299616 | AE25: -298472
C26: Ending ARR | G26: $ | H26: =INDEX($N26:$BU26,MATCH(H$12,N$12:$BU$12,0)) -> 17099065 | I26: =INDEX($N26:$BU26,MATCH(I$12,O$12:$BU$12,0)) | J26: =INDEX($N26:$BU26,MATCH(J$12,P$12:$BU$12,0)) | K26: =INDEX($N26:$BU26,MATCH(K$12,Q$12:$BU$12,0)) | L26: =INDEX($N26:$BU26,MATCH(L$12,R$12:$BU$12,0)) | N26: =SUM(N22:N25) -> 12248800 | O26: =SUM(O22:O25) -> 12691380 | P26: =SUM(P22:P25) -> 13205436 | Q26: =SUM(Q22:Q25) -> 13595598 | R26: =SUM(R22:R25) -> 13929304 | S26: =SUM(S22:S25) -> 14504143 | T26: =SUM(T22:T25) -> 15198474 | U26: =SUM(U22:U25) -> 15699593 | ... AE26: =SUM(AE22:AE25) -> 19592945
C28: Customer Summary
C29: Beginning Customers | G29: $ | H29: =SUMIFS($N29:$BI29,$N$19:$BI$19,H$19) -> 6817 | I29: =SUMIFS($N29:$BI29,$N$19:$BI$19,I$19) -> 4045 | J29: =SUMIFS($N29:$BI29,$N$19:$BI$19,J$19) -> 0 | K29: =SUMIFS($N29:$BI29,$N$19:$BI$19,K$19) -> 0 | L29: =SUMIFS($N29:$BI29,$N$19:$BI$19,L$19) -> 0 | N29: 500 | O29: =N32 -> 509 | P29: =O32 -> 519 | Q29: =P32 -> 531 | R29: =Q32 -> 543 | S29: =R32 -> 556 | T29: =S32 -> 576 | U29: =T32 -> 595 | V29: =U32 -> 606 | ... AE29: =AD32 -> 704
C30: New Customers | G30: $ | H30: =SUMIFS($N30:$BI30,$N$19:$BI$19,H$19) -> 248 | I30: =SUMIFS($N30:$BI30,$N$19:$BI$19,I$19) -> 126 | J30: =SUMIFS($N30:$BI30,$N$19:$BI$19,J$19) -> 0 | K30: =SUMIFS($N30:$BI30,$N$19:$BI$19,K$19) -> 0 | L30: =SUMIFS($N30:$BI30,$N$19:$BI$19,L$19) -> 0 | N30: =N41 -> 16 | O30: =O41 -> 21 | P30: =P41 -> 23 | Q30: =Q41 -> 19 | R30: =R41 -> 18 | S30: =S41 -> 28 | T30: =T41 -> 25 | U30: =U41 -> 23 | ... AE30: =AE41 -> 23
C31: Churned Customers | G31: $ | H31: =SUMIFS($N31:$BI31,$N$19:$BI$19,H$19) -> -100 | I31: =SUMIFS($N31:$BI31,$N$19:$BI$19,I$19) -> -58 | J31: =SUMIFS($N31:$BI31,$N$19:$BI$19,J$19) -> 0 | K31: =SUMIFS($N31:$BI31,$N$19:$BI$19,K$19) -> 0 | L31: =SUMIFS($N31:$BI31,$N$19:$BI$19,L$19) -> 0 | N31: =-N49 -> -7 | O31: =-O49 -> -11 | P31: =-P49 -> -11 | Q31: =-Q49 -> -7 | R31: =-R49 -> -5 | S31: =-S49 -> -8 | T31: =-T49 -> -6 | U31: =-U49 -> -12 | ... AE31: =-AE49 -> -11
C32: Ending Customers | G32: $ | H32: =SUMIFS($N32:$BI32,$N$19:$BI$19,H$19) -> 6965 | I32: =SUMIFS($N32:$BI32,$N$19:$BI$19,I$19) -> 4113 | J32: =SUMIFS($N32:$BI32,$N$19:$BI$19,J$19) -> 0 | K32: =SUMIFS($N32:$BI32,$N$19:$BI$19,K$19) -> 0 | L32: =SUMIFS($N32:$BI32,$N$19:$BI$19,L$19) -> 0 | N32: =SUM(N29:N31) -> 509 | O32: =SUM(O29:O31) -> 519 | P32: =SUM(P29:P31) -> 531 | Q32: =SUM(Q29:Q31) -> 543 | R32: =SUM(R29:R31) -> 556 | S32: =SUM(S29:S31) -> 576 | T32: =SUM(T29:T31) -> 595 | U32: =SUM(U29:U31) -> 606 | ... AE32: =SUM(AE29:AE31) -> 716
C34: Average Contract Value Summary
C35: Historical ACV | G35: $ | H35: =iferror(AVERAGEIFS($N35:$BI35,$N$19:$BI$19,H$19),0) -> 25431.513 | I35: =iferror(AVERAGEIFS($N35:$BI35,$N$19:$BI$19,I$19),0) -> 27219.758 | J35: =iferror(AVERAGEIFS($N35:$BI35,$N$19:$BI$19,J$19),0) -> 0 | K35: =iferror(AVERAGEIFS($N35:$BI35,$N$19:$BI$19,K$19),0) -> 0 | L35: =iferror(AVERAGEIFS($N35:$BI35,$N$19:$BI$19,L$19),0) -> 0 | N35: =N26/N32 -> 24064.44 | O35: =O26/O32 -> 24453.525 | P35: =P26/P32 -> 24868.994 | Q35: =Q26/Q32 -> 25037.935 | R35: =R26/R32 -> 25052.705 | S35: =S26/S32 -> 25180.803 | T35: =T26/T32 -> 25543.654 | U35: =U26/U32 -> 25906.919 | ... AE35: =AE26/AE32 -> 27364.449
C37: New Customers Calculation
C38: Pipeline Leads | G38: # | H38: =SUMIFS($N38:$BI38,$N$19:$BI$19,H$19) -> 6108 | I38: =SUMIFS($N38:$BI38,$N$19:$BI$19,I$19) -> 2986 | J38: =SUMIFS($N38:$BI38,$N$19:$BI$19,J$19) -> 0 | K38: =SUMIFS($N38:$BI38,$N$19:$BI$19,K$19) -> 0 | L38: =SUMIFS($N38:$BI38,$N$19:$BI$19,L$19) -> 0 | N38: 466 | O38: 534 | P38: 485 | Q38: 507 | R38: 515 | S38: 542 | T38: 466 | U38: 541 | V38: 536 | W38: 469 | X38: 525 | Y38: 522 | Z38: 508 | AA38: 450 | AB38: 450 | AC38: 520 | AD38: 531 | AE38: 527
C39: MQL | G39: # | H39: =SUMIFS($N39:$BI39,$N$19:$BI$19,H$19) -> 787 | I39: =SUMIFS($N39:$BI39,$N$19:$BI$19,I$19) -> 395 | J39: =SUMIFS($N39:$BI39,$N$19:$BI$19,J$19) -> 0 | K39: =SUMIFS($N39:$BI39,$N$19:$BI$19,K$19) -> 0 | L39: =SUMIFS($N39:$BI39,$N$19:$BI$19,L$19) -> 0 | N39: 61 | O39: 80 | P39: 68 | Q39: 61 | R39: 62 | S39: 76 | T39: 70 | U39: 70 | V39: 54 | W39: 70 | X39: 63 | Y39: 52 | Z39: 71 | AA39: 54 | AB39: 54 | AC39: 78 | AD39: 69 | AE39: 69
C40: SQL | G40: # | H40: =SUMIFS($N40:$BI40,$N$19:$BI$19,H$19) -> 353 | I40: =SUMIFS($N40:$BI40,$N$19:$BI$19,I$19) -> 179 | J40: =SUMIFS($N40:$BI40,$N$19:$BI$19,J$19) -> 0 | K40: =SUMIFS($N40:$BI40,$N$19:$BI$19,K$19) -> 0 | L40: =SUMIFS($N40:$BI40,$N$19:$BI$19,L$19) -> 0 | N40: 22 | O40: 31 | P40: 31 | Q40: 28 | R40: 24 | S40: 41 | T40: 37 | U40: 33 | V40: 25 | W40: 36 | X40: 23 | Y40: 22 | Z40: 33 | AA40: 27 | AB40: 19 | AC40: 28 | AD40: 38 | AE40: 34
C41: Deals / New Customers | G41: # | H41: =SUMIFS($N41:$BI41,$N$19:$BI$19,H$19) -> 248 | I41: =SUMIFS($N41:$BI41,$N$19:$BI$19,I$19) -> 126 | J41: =SUMIFS($N41:$BI41,$N$19:$BI$19,J$19) -> 0 | K41: =SUMIFS($N41:$BI41,$N$19:$BI$19,K$19) -> 0 | L41: =SUMIFS($N41:$BI41,$N$19:$BI$19,L$19) -> 0 | N41: 16 | O41: 21 | P41: 23 | Q41: 19 | R41: 18 | S41: 28 | T41: 25 | U41: 23 | V41: 19 | W41: 23 | X41: 17 | Y41: 16 | Z41: 22 | AA41: 20 | AB41: 13 | AC41: 21 | AD41: 27 | AE41: 23
C43: Pipeline to MQL (conversion rate %) | G43: % | H43: =iferror(AVERAGEIFS($N43:$BI43,$N$19:$BI$19,H$19),0) -> 0.12925558 | I43: =iferror(AVERAGEIFS($N43:$BI43,$N$19:$BI$19,I$19),0) -> 0.13177285 | J43: =iferror(AVERAGEIFS($N43:$BI43,$N$19:$BI$19,J$19),0) -> 0 | K43: =iferror(AVERAGEIFS($N43:$BI43,$N$19:$BI$19,K$19),0) -> 0 | L43: =iferror(AVERAGEIFS($N43:$BI43,$N$19:$BI$19,L$19),0) -> 0 | N43: =N39/N38 -> 0.13090129 | O43: =O39/O38 -> 0.14981273 | P43: =P39/P38 -> 0.14020619 | Q43: =Q39/Q38 -> 0.12031558 | R43: =R39/R38 -> 0.12038835 | S43: =S39/S38 -> 0.1402214 | T43: =T39/T38 -> 0.15021459 | U43: =U39/U38 -> 0.12939002 | ... AE43: =AE39/AE38 -> 0.13092979
C44: MQL to SQL (conversion rate %) | G44: % | H44: =iferror(AVERAGEIFS($N44:$BI44,$N$19:$BI$19,H$19),0) -> 0.44625249 | I44: =iferror(AVERAGEIFS($N44:$BI44,$N$19:$BI$19,I$19),0) -> 0.4531822 | J44: =iferror(AVERAGEIFS($N44:$BI44,$N$19:$BI$19,J$19),0) -> 0 | K44: =iferror(AVERAGEIFS($N44:$BI44,$N$19:$BI$19,K$19),0) -> 0 | L44: =iferror(AVERAGEIFS($N44:$BI44,$N$19:$BI$19,L$19),0) -> 0 | N44: =N40/N39 -> 0.36065574 | O44: =O40/O39 -> 0.3875 | P44: =P40/P39 -> 0.45588235 | Q44: =Q40/Q39 -> 0.45901639 | R44: =R40/R39 -> 0.38709677 | S44: =S40/S39 -> 0.53947368 | T44: =T40/T39 -> 0.52857143 | U44: =U40/U39 -> 0.47142857 | ... AE44: =AE40/AE39 -> 0.49275362
C45: SQL to Deals (conversion rate %) | G45: % | H45: =iferror(AVERAGEIFS($N45:$BI45,$N$19:$BI$19,H$19),0) -> 0.70800527 | I45: =iferror(AVERAGEIFS($N45:$BI45,$N$19:$BI$19,I$19),0) -> 0.70476914 | J45: =iferror(AVERAGEIFS($N45:$BI45,$N$19:$BI$19,J$19),0) -> 0 | K45: =iferror(AVERAGEIFS($N45:$BI45,$N$19:$BI$19,K$19),0) -> 0 | L45: =iferror(AVERAGEIFS($N45:$BI45,$N$19:$BI$19,L$19),0) -> 0 | N45: =N41/N40 -> 0.72727273 | O45: =O41/O40 -> 0.67741935 | P45: =P41/P40 -> 0.74193548 | Q45: =Q41/Q40 -> 0.67857143 | R45: =R41/R40 -> 0.75 | S45: =S41/S40 -> 0.68292683 | T45: =T41/T40 -> 0.67567568 | U45: =U41/U40 -> 0.6969697 | ... AE45: =AE41/AE40 -> 0.67647059
C48: Churned Customers Calculation
C49: Historical / Forecasted Churn | G49: # | H49: =SUMIFS($N49:$BU49,$N$19:$BU$19,H$19) -> 100 | I49: =SUMIFS($N49:$BU49,$N$19:$BU$19,I$19) -> 58 | J49: =SUMIFS($N49:$BU49,$N$19:$BU$19,J$19) -> 0 | K49: =SUMIFS($N49:$BU49,$N$19:$BU$19,K$19) -> 0 | L49: =SUMIFS($N49:$BU49,$N$19:$BU$19,L$19) -> 0 | N49: 7 | O49: 11 | P49: 11 | Q49: 7 | R49: 5 | S49: 8 | T49: 6 | U49: 12 | V49: 10 | W49: 9 | X49: 8 | Y49: 6 | Z49: 12 | AA49: 6 | AB49: 9 | AC49: 10 | AD49: 10 | AE49: 11
C50: Churn Rate (% of total customer base) | G50: % | H50: =iferror(AVERAGEIFS($N50:$BI50,$N$19:$BI$19,H$19),0) -> 0.014785699 | I50: =iferror(AVERAGEIFS($N50:$BI50,$N$19:$BI$19,I$19),0) -> 0.014333976 | J50: =iferror(AVERAGEIFS($N50:$BI50,$N$19:$BI$19,J$19),0) -> 0 | K50: =iferror(AVERAGEIFS($N50:$BI50,$N$19:$BI$19,K$19),0) -> 0 | L50: =iferror(AVERAGEIFS($N50:$BI50,$N$19:$BI$19,L$19),0) -> 0 | N50: =N49/N29 -> 0.014 | O50: =O49/O29 -> 0.021611002 | P50: =P49/P29 -> 0.021194605 | Q50: =Q49/Q29 -> 0.013182674 | R50: =R49/R29 -> 0.0092081031 | S50: =S49/S29 -> 0.014388489 | T50: =T49/T29 -> 0.010416667 | U50: =U49/U29 -> 0.020168067 | ... AE50: =AE49/AE29 -> 0.015625
C53: P&L
C54: Revenue | G54: $'000s | H54: =SUMIFS($N54:$BU54,$N$19:$BU$19,H$19) -> 13273.974 | I54: =SUMIFS($N54:$BU54,$N$19:$BU$19,I$19) -> 7487.8048 | J54: =SUMIFS($N54:$BU54,$N$19:$BU$19,J$19) -> 0 | K54: =SUMIFS($N54:$BU54,$N$19:$BU$19,K$19) -> 0 | L54: =SUMIFS($N54:$BU54,$N$19:$BU$19,L$19) -> 0 | N54: 997.50317 | O54: 1019.9178 | P54: 1043.3004 | Q54: 1059.1199 | R54: 1074.4782 | S54: 1102.9111 | T54: 1139.7489 | U54: 1162.8912 | V54: 1158.3469 | W54: 1167.8844 | X54: 1167.0779 | Y54: 1180.794 | Z54: 1207.7078 | AA54: 1238.7052 | AB54: 1239.4029 | AC54: 1255.1652 | AD54: 1271.9272 | AE54: 1274.8965
...

Sheet Summary
B2: Summary table SaaS Financial Model
G5: =IF(G13=1,"Actual","Forecast") -> Actual | H5: =IF(H13=1,"Actual","Forecast") -> Actual | I5: =IF(I13=1,"Actual","Forecast") -> Forecast | J5: =IF(J13=1,"Actual","Forecast") -> Forecast | K5: =IF(K13=1,"Actual","Forecast") -> Forecast | M5: =IF(M13=1,"Actual","Forecast") -> Actual | N5: =IF(N13=1,"Actual","Forecast") -> Actual | O5: =IF(O13=1,"Actual","Forecast") -> Actual | P5: =IF(P13=1,"Actual","Forecast") -> Actual | Q5: =IF(Q13=1,"Actual","Forecast") -> Actual | R5: =IF(R13=1,"Actual","Forecast") -> Actual | S5: =IF(S13=1,"Actual","Forecast") -> Actual | T5: =IF(T13=1,"Actual","Forecast") -> Actual | ... BT5: =IF(BT13=1,"Actual","Forecast") -> Forecast
G6: =G7 -> 44562 | H6: =H7 -> 44927 | I6: =I7 -> 45292 | J6: =J7 -> 45658 | K6: =K7 -> 46023 | M6: =M7 -> 44562 | N6: =N7 -> 44593 | O6: =O7 -> 44621 | P6: =P7 -> 44652 | Q6: =Q7 -> 44682 | R6: =R7 -> 44713 | S6: =S7 -> 44743 | T6: =T7 -> 44774 | ... BT6: =BT7 -> 46357
F7: Start Date | G7: ='Key Assumptions'!D13 -> 44562 | H7: =G8+1 -> 44927 | I7: =H8+1 -> 45292 | J7: =I8+1 -> 45658 | K7: =J8+1 -> 46023 | M7: ='Key Assumptions'!D13 -> 44562 | N7: =M8+1 -> 44593 | O7: =N8+1 -> 44621 | P7: =O8+1 -> 44652 | Q7: =P8+1 -> 44682 | R7: =Q8+1 -> 44713 | S7: =R8+1 -> 44743 | T7: =S8+1 -> 44774 | U7: =T8+1 -> 44805 | ... BT7: =BS8+1 -> 46357
F8: End Date | G8: =EOMONTH(G7,11) -> 44926 | H8: =EOMONTH(H7,11) -> 45291 | I8: =EOMONTH(I7,11) -> 45657 | J8: =EOMONTH(J7,11) -> 46022 | K8: =EOMONTH(K7,11) -> 46387 | M8: =EOMONTH(M7,0) -> 44592 | N8: =EOMONTH(N7,0) -> 44620 | O8: =EOMONTH(O7,0) -> 44651 | P8: =EOMONTH(P7,0) -> 44681 | Q8: =EOMONTH(Q7,0) -> 44712 | R8: =EOMONTH(R7,0) -> 44742 | S8: =EOMONTH(S7,0) -> 44773 | T8: =EOMONTH(T7,0) -> 44804 | ... BT8: =EOMONTH(BT7,0) -> 46387
F9: Timeline | G9: =IF(G8-G7>35,"Annual","Monthly") -> Annual | H9: =IF(H8-H7>35,"Annual","Monthly") -> Annual | I9: =IF(I8-I7>35,"Annual","Monthly") -> Annual | J9: =IF(J8-J7>35,"Annual","Monthly") -> Annual | K9: =IF(K8-K7>35,"Annual","Monthly") -> Annual | M9: =IF(M8-M7>35,"Annual","Monthly") -> Monthly | N9: =IF(N8-N7>35,"Annual","Monthly") -> Monthly | O9: =IF(O8-O7>35,"Annual","Monthly") -> Monthly | P9: =IF(P8-P7>35,"Annual","Monthly") -> Monthly | Q9: =IF(Q8-Q7>35,"Annual","Monthly") -> Monthly | R9: =IF(R8-R7>35,"Annual","Monthly") -> Monthly | S9: =IF(S8-S7>35,"Annual","Monthly") -> Monthly | T9: =IF(T8-T7>35,"Annual","Monthly") -> Monthly | ... BT9: =IF(BT8-BT7>35,"Annual","Monthly") -> Monthly
F10: Year | G10: =YEAR(G7) -> 2022 | H10: =YEAR(H7) -> 2023 | I10: =YEAR(I7) -> 2024 | J10: =YEAR(J7) -> 2025 | K10: =YEAR(K7) -> 2026 | M10: =YEAR(M7) -> 2022 | N10: =YEAR(N7) -> 2022 | O10: =YEAR(O7) -> 2022 | P10: =YEAR(P7) -> 2022 | Q10: =YEAR(Q7) -> 2022 | R10: =YEAR(R7) -> 2022 | S10: =YEAR(S7) -> 2022 | T10: =YEAR(T7) -> 2022 | ... BT10: =YEAR(BT7) -> 2026
F12: Flag
F13: Historical Flag | G13: =IF(AND(G7>='Key Assumptions'!$D$13,G7<'Key Assumptions'!$D$14),1,0) -> 1 | H13: =IF(AND(H7>='Key Assumptions'!$D$13,H7<'Key Assumptions'!$D$14),1,0) -> 1 | I13: =IF(AND(I7>='Key Assumptions'!$D$13,I7<'Key Assumptions'!$D$14),1,0) -> 0 | J13: =IF(AND(J7>='Key Assumptions'!$D$13,J7<'Key Assumptions'!$D$14),1,0) -> 0 | K13: =IF(AND(K7>='Key Assumptions'!$D$13,K7<'Key Assumptions'!$D$14),1,0) -> 0 | M13: =IF(AND(M7>='Key Assumptions'!$D$13,M7<'Key Assumptions'!$D$14),1,0) -> 1 | N13: =IF(AND(N7>='Key Assumptions'!$D$13,N7<'Key Assumptions'!$D$14),1,0) -> 1 | O13: =IF(AND(O7>='Key Assumptions'!$D$13,O7<'Key Assumptions'!$D$14),1,0) -> 1 | P13: =IF(AND(P7>='Key Assumptions'!$D$13,P7<'Key Assumptions'!$D$14),1,0) -> 1 | Q13: =IF(AND(Q7>='Key Assumptions'!$D$13,Q7<'Key Assumptions'!$D$14),1,0) -> 1 | R13: =IF(AND(R7>='Key Assumptions'!$D$13,R7<'Key Assumptions'!$D$14),1,0) -> 1 | S13: =IF(AND(S7>='Key Assumptions'!$D$13,S7<'Key Assumptions'!$D$14),1,0) -> 1 | T13: =IF(AND(T7>='Key Assumptions'!$D$13,T7<'Key Assumptions'!$D$14),1,0) -> 1 | ... BT13: =IF(AND(BT7>='Key Assumptions'!$D$13,BT7<'Key Assumptions'!$D$14),1,0) -> 0
F14: Forecast Flag | G14: =IF(AND(G7>='Key Assumptions'!$D$15,G7<'Key Assumptions'!$D$16),1,0) -> 0 | H14: =IF(AND(H7>='Key Assumptions'!$D$15,H7<'Key Assumptions'!$D$16),1,0) -> 0 | I14: =IF(AND(I7>='Key Assumptions'!$D$15,I7<'Key Assumptions'!$D$16),1,0) -> 1 | J14: =IF(AND(J7>='Key Assumptions'!$D$15,J7<'Key Assumptions'!$D$16),1,0) -> 1 | K14: =IF(AND(K7>='Key Assumptions'!$D$15,K7<'Key Assumptions'!$D$16),1,0) -> 1 | M14: =IF(AND(M7>='Key Assumptions'!$D$15,M7<'Key Assumptions'!$D$16),1,0) -> 0 | N14: =IF(AND(N7>='Key Assumptions'!$D$15,N7<'Key Assumptions'!$D$16),1,0) -> 0 | O14: =IF(AND(O7>='Key Assumptions'!$D$15,O7<'Key Assumptions'!$D$16),1,0) -> 0 | P14: =IF(AND(P7>='Key Assumptions'!$D$15,P7<'Key Assumptions'!$D$16),1,0) -> 0 | Q14: =IF(AND(Q7>='Key Assumptions'!$D$15,Q7<'Key Assumptions'!$D$16),1,0) -> 0 | R14: =IF(AND(R7>='Key Assumptions'!$D$15,R7<'Key Assumptions'!$D$16),1,0) -> 0 | S14: =IF(AND(S7>='Key Assumptions'!$D$15,S7<'Key Assumptions'!$D$16),1,0) -> 0 | T14: =IF(AND(T7>='Key Assumptions'!$D$15,T7<'Key Assumptions'!$D$16),1,0) -> 0 | ... BT14: =IF(AND(BT7>='Key Assumptions'!$D$15,BT7<'Key Assumptions'!$D$16),1,0) -> 1
F15: Year Flag | G15: =COUNTA($G$7:G7) -> 1 | H15: =COUNTA($G$7:H7) -> 2 | I15: =COUNTA($G$7:I7) -> 3 | J15: =COUNTA($G$7:J7) -> 4 | K15: =COUNTA($G$7:K7) -> 5 | M15: =INDEX($G$15:$K$15,MATCH(YEAR(M$7),$G$10:$K$10,0)) -> 1 | N15: =INDEX($G$15:$K$15,MATCH(YEAR(N$7),$G$10:$K$10,0)) -> 1 | O15: =INDEX($G$15:$K$15,MATCH(YEAR(O$7),$G$10:$K$10,0)) -> 1 | P15: =INDEX($G$15:$K$15,MATCH(YEAR(P$7),$G$10:$K$10,0)) -> 1 | Q15: =INDEX($G$15:$K$15,MATCH(YEAR(Q$7),$G$10:$K$10,0)) -> 1 | R15: =INDEX($G$15:$K$15,MATCH(YEAR(R$7),$G$10:$K$10,0)) -> 1 | S15: =INDEX($G$15:$K$15,MATCH(YEAR(S$7),$G$10:$K$10,0)) -> 1 | T15: =INDEX($G$15:$K$15,MATCH(YEAR(T$7),$G$10:$K$10,0)) -> 1 | ... BT15: =INDEX($G$15:$K$15,MATCH(YEAR(BT$7),$G$10:$K$10,0)) -> 5
B17: ARR Summary
B18: Beginning ARR | F18: $ | G18: =INDEX($M18:$BT18,MATCH(G$7,$M$7:$BT$7,0)) -> 11935000 | H18: =INDEX($M18:$BT18,MATCH(H$7,$M$7:$BT$7,0)) -> 17099065 | I18: =INDEX($M18:$BT18,MATCH(I$7,$M$7:$BT$7,0)) -> 22916197 | J18: =INDEX($M18:$BT18,MATCH(J$7,$M$7:$BT$7,0)) -> 29614278 | K18: =INDEX($M18:$BT18,MATCH(K$7,$M$7:$BT$7,0)) -> 36412072 | M18: =IF(M$13=1,Actuals!N22,L22) -> 11935000 | N18: =IF(N$13=1,Actuals!O22,M22) -> 12248800 | O18: =IF(O$13=1,Actuals!P22,N22) -> 12691380 | P18: =IF(P$13=1,Actuals!Q22,O22) -> 13205436 | Q18: =IF(Q$13=1,Actuals!R22,P22) -> 13595598 | R18: =IF(R$13=1,Actuals!S22,Q22) -> 13929304 | S18: =IF(S$13=1,Actuals!T22,R22) -> 14504143 | T18: =IF(T$13=1,Actuals!U22,S22) -> 15198474 | ... BT18: =IF(BT$13=1,Actuals!BU22,BS22) -> 42643185
B19: New ARR | F19: $ | G19: =SUMIFS($M19:$BT19,$M$15:$BT$15,G$15) -> 5288050 | H19: =SUMIFS($M19:$BT19,$M$15:$BT$15,H$15) -> 5764112.4 | I19: =SUMIFS($M19:$BT19,$M$15:$BT$15,I$15) -> 6240682.6 | J19: =SUMIFS($M19:$BT19,$M$15:$BT$15,J$15) -> 6240695.3 | K19: =SUMIFS($M19:$BT19,$M$15:$BT$15,K$15) -> 6240695.3 | M19: =IF(M$13=1,Actuals!N23,M$33*M28) -> 405790 | N19: =IF(N$13=1,Actuals!O23,N$33*N28) -> 394080 | O19: =IF(O$13=1,Actuals!P23,O$33*O28) -> 529966 | P19: =IF(P$13=1,Actuals!Q23,P$33*P28) -> 454746 | Q19: =IF(Q$13=1,Actuals!R23,Q$33*Q28) -> 339150 | R19: =IF(R$13=1,Actuals!S23,R$33*R28) -> 530374 | S19: =IF(S$13=1,Actuals!T23,S$33*S28) -> 572670 | T19: =IF(T$13=1,Actuals!U23,T$33*T28) -> 507144 | ... BT19: =IF(BT$13=1,Actuals!BU23,BT$33*BT28) -> 520057.94
B20: Expansion | F20: $ | G20: =SUMIFS($M20:$BT20,$M$15:$BT$15,G$15) -> 2329537.4 | H20: =SUMIFS($M20:$BT20,$M$15:$BT$15,H$15) -> 2335236.3 | I20: =SUMIFS($M20:$BT20,$M$15:$BT$15,I$15) -> 2346644.4 | J20: =SUMIFS($M20:$BT20,$M$15:$BT$15,J$15) -> 2347249.8 | K20: =SUMIFS($M20:$BT20,$M$15:$BT$15,K$15) -> 2347245.1 | M20: =IF(M$13=1,Actuals!N24,'Key Assumptions'!O29) -> 178762.11 | N20: =IF(N$13=1,Actuals!O24,'Key Assumptions'!P29) -> 173603.52 | O20: =IF(O$13=1,Actuals!P24,'Key Assumptions'!Q29) -> 233465.2 | P20: =IF(P$13=1,Actuals!Q24,'Key Assumptions'!R29) -> 200328.63 | Q20: =IF(Q$13=1,Actuals!R24,'Key Assumptions'!S29) -> 149405.29 | R20: =IF(R$13=1,Actuals!S24,'Key Assumptions'!T29) -> 233644.93 | S20: =IF(S$13=1,Actuals!T24,'Key Assumptions'!U29) -> 252277.53 | T20: =IF(T$13=1,Actuals!U24,'Key Assumptions'!V29) -> 223411.45 | ... BT20: =IF(BT$13=1,Actuals!BU24,'Key Assumptions'!BV29) -> 195603.73
B21: Churn ARR | F21: $ | G21: =SUMIFS($M21:$BT21,$M$15:$BT$15,G$15) -> -2453522 | H21: =SUMIFS($M21:$BT21,$M$15:$BT$15,H$15) -> -2282217.2 | I21: =SUMIFS($M21:$BT21,$M$15:$BT$15,I$15) -> -1889245.9 | J21: =SUMIFS($M21:$BT21,$M$15:$BT$15,J$15) -> -1790150.8 | K21: =SUMIFS($M21:$BT21,$M$15:$BT$15,K$15) -> -1790229.3 | M21: =IF(M$13=1,Actuals!N25,M$33*M29) -> -270752 | N21: =IF(N$13=1,Actuals!O25,N$33*N29) -> -125104 | O21: =IF(O$13=1,Actuals!P25,O$33*O29) -> -249375 | P21: =IF(P$13=1,Actuals!Q25,P$33*P29) -> -264912 | Q21: =IF(Q$13=1,Actuals!R25,Q$33*Q29) -> -154850 | R21: =IF(R$13=1,Actuals!S25,R$33*R29) -> -189180 | S21: =IF(S$13=1,Actuals!T25,S$33*S29) -> -130616 | T21: =IF(T$13=1,Actuals!U25,T$33*T29) -> -229437 | ... BT21: =IF(BT$13=1,Actuals!BU25,BT$33*BT29) -> -149063.19
B22: Ending ARR | F22: $ | G22: =INDEX($M22:$BT22,MATCH(G$8,$M$8:$BT$8,0)) -> 17099065 | H22: =INDEX($M22:$BT22,MATCH(H$8,$M$8:$BT$8,0)) -> 22916197 | I22: =INDEX($M22:$BT22,MATCH(I$8,$M$8:$BT$8,0)) -> 29614278 | J22: =INDEX($M22:$BT22,MATCH(J$8,$M$8:$BT$8,0)) -> 36412072 | K22: =INDEX($M22:$BT22,MATCH(K$8,$M$8:$BT$8,0)) -> 43209783 | M22: =IF(M$13=1,Actuals!N26,sum(M18:M21)) -> 12248800 | N22: =IF(N$13=1,Actuals!O26,sum(N18:N21)) -> 12691380 | O22: =IF(O$13=1,Actuals!P26,sum(O18:O21)) -> 13205436 | P22: =IF(P$13=1,Actuals!Q26,sum(P18:P21)) -> 13595598 | Q22: =IF(Q$13=1,Actuals!R26,sum(Q18:Q21)) -> 13929304 | R22: =IF(R$13=1,Actuals!S26,sum(R18:R21)) -> 14504143 | S22: =IF(S$13=1,Actuals!T26,sum(S18:S21)) -> 15198474 | T22: =IF(T$13=1,Actuals!U26,sum(T18:T21)) -> 15699593 | ... BT22: =IF(BT$13=1,Actuals!BU26,sum(BT18:BT21)) -> 43209783
B24: ='Customer Control'!B23 -> Net new customers | F24: # | G24: ='Customer Control'!F23 -> 148 | H24: ='Customer Control'!G23 -> 146.64575 | I24: ='Customer Control'!H23 -> 158.97737 | J24: ='Customer Control'!I23 -> 162.59793 | K24: ='Customer Control'!J23 -> 162.59507 | M24: ='Customer Control'!L23 -> 9 | N24: ='Customer Control'!M23 -> 10 | O24: ='Customer Control'!N23 -> 12 | P24: ='Customer Control'!O23 -> 12 | Q24: ='Customer Control'!P23 -> 13 | R24: ='Customer Control'!Q23 -> 20 | S24: ='Customer Control'!R23 -> 19 | T24: ='Customer Control'!S23 -> 11 | ... BT24: ='Customer Control'!BS23 -> 13.554067
B26: Customer Summary
B27: Beginning Customers | F27: # | G27: {=INDEX($M27:$BT27,MATCH(G$7,M$7:BH$7,0))} -> 500 | H27: =INDEX($M27:$BH27,MATCH(H$7,N$7:BU$7,0)) -> 638 | I27: =INDEX($M27:$BH27,MATCH(I$7,O$7:BV$7,0)) -> 766.13997 | J27: =INDEX($M27:$BH27,MATCH(J$7,P$7:BW$7,0)) -> 912.91999 | K27: =INDEX($M27:$BH27,MATCH(K$7,Q$7:BX$7,0)) -> 1062.0217 | M27: ='Customer Control'!L18 -> 500 | N27: ='Customer Control'!M18 -> 509 | O27: ='Customer Control'!N18 -> 519 | P27: ='Customer Control'!O18 -> 531 | Q27: ='Customer Control'!P18 -> 543 | R27: ='Customer Control'!Q18 -> 556 | S27: ='Customer Control'!R18 -> 576 | T27: ='Customer Control'!S18 -> 595 | ... BT27: ='Customer Control'!BS18 -> 1265.262
B28: New Customers | F28: # | G28: =SUMIFS($M28:$BT28,$M$15:$BT$15,G$15) -> 248 | H28: =SUMIFS($M28:$BT28,$M$15:$BT$15,H$15) -> 240 | I28: =SUMIFS($M28:$BT28,$M$15:$BT$15,I$15) -> 228 | J28: =SUMIFS($M28:$BT28,$M$15:$BT$15,J$15) -> 228 | K28: =SUMIFS($M28:$BT28,$M$15:$BT$15,K$15) -> 228 | M28: ='Customer Control'!L19 -> 16 | N28: ='Customer Control'!M19 -> 21 | O28: ='Customer Control'!N19 -> 23 | P28: ='Customer Control'!O19 -> 19 | Q28: ='Customer Control'!P19 -> 18 | R28: ='Customer Control'!Q19 -> 28 | S28: ='Customer Control'!R19 -> 25 | T28: ='Customer Control'!S19 -> 23 | ... BT28: ='Customer Control'!BS19 -> 19
B29: Churned Customers | F29: # | G29: =SUMIFS($M29:$BT29,$M$15:$BT$15,G$15) -> -100 | H29: =SUMIFS($M29:$BT29,$M$15:$BT$15,H$15) -> -93.354255 | I29: =SUMIFS($M29:$BT29,$M$15:$BT$15,I$15) -> -69.022628 | J29: =SUMIFS($M29:$BT29,$M$15:$BT$15,J$15) -> -65.40207 | K29: =SUMIFS($M29:$BT29,$M$15:$BT$15,K$15) -> -65.404935 | M29: ='Customer Control'!L20 -> -7 | N29: ='Customer Control'!M20 -> -11 | O29: ='Customer Control'!N20 -> -11 | P29: ='Customer Control'!O20 -> -7 | Q29: ='Customer Control'!P20 -> -5 | R29: ='Customer Control'!Q20 -> -8 | S29: ='Customer Control'!R20 -> -6 | T29: ='Customer Control'!S20 -> -12 | ... BT29: ='Customer Control'!BS20 -> -5.4459327
B30: Ending Customers | F30: # | G30: =INDEX($M30:$BT30,MATCH(G$8,M$8:BT$8,0)) -> 648 | H30: =INDEX($M30:$BT30,MATCH(H$8,N$8:BU$8,0)) -> 780.14179 | I30: =INDEX($M30:$BT30,MATCH(I$8,O$8:BV$8,0)) -> 926.48655 | J30: =INDEX($M30:$BT30,MATCH(J$8,P$8:BW$8,0)) -> 1075.5822 | K30: =INDEX($M30:$BT30,MATCH(K$8,Q$8:BX$8,0)) -> 1224.6219 | M30: ='Customer Control'!L21 -> 509 | N30: ='Customer Control'!M21 -> 519 | O30: ='Customer Control'!N21 -> 531 | P30: ='Customer Control'!O21 -> 543 | Q30: ='Customer Control'!P21 -> 556 | R30: ='Customer Control'!Q21 -> 576 | S30: ='Customer Control'!R21 -> 595 | T30: ='Customer Control'!S21 -> 606 | ... BT30: ='Customer Control'!BS21 -> 1278.8161
B32: Average Contract Value Summary
B33: Forecasted ACV | F33: $ | G33: =iferror(AVERAGEIFS($M33:$BT33,$M$15:$BT$15,G$15),0) -> 25431.513 | H33: =iferror(AVERAGEIFS($M33:$BT33,$M$15:$BT$15,H$15),0) -> 27295.657 | I33: =iferror(AVERAGEIFS($M33:$BT33,$M$15:$BT$15,I$15),0) -> 27371.415 | J33: =iferror(AVERAGEIFS($M33:$BT33,$M$15:$BT$15,J$15),0) -> 27371.471 | K33: =iferror(AVERAGEIFS($M33:$BT33,$M$15:$BT$15,K$15),0) -> 27371.471 | M33: =IF(M13=1,Actuals!N35,AVERAGE(H33:L33)) -> 24064.44 | N33: =IF(N13=1,Actuals!O35,AVERAGE(I33:M33)) -> 24453.525 | O33: =IF(O13=1,Actuals!P35,AVERAGE(J33:N33)) -> 24868.994 | P33: =IF(P13=1,Actuals!Q35,AVERAGE(L33:O33)) -> 25037.935 | Q33: =IF(Q13=1,Actuals!R35,AVERAGE(M33:P33)) -> 25052.705 | R33: =IF(R13=1,Actuals!S35,AVERAGE(N33:Q33)) -> 25180.803 | S33: =IF(S13=1,Actuals!T35,AVERAGE(O33:R33)) -> 25543.654 | T33: =IF(T13=1,Actuals!U35,AVERAGE(P33:S33)) -> 25906.919 | U33: =IF(U13=1,Actuals!V35,AVERAGE(Q33:T33)) -> 26012.974 | V33: =IF(V13=1,Actuals!W35,AVERAGE(R33:U33)) -> 26330.841 | W33: =IF(W13=1,Actuals!X35,AVERAGE(S33:V33)) -> 26337.914 | ... BI33: =IF(BI13=1,Actuals!BJ35,AVERAGE(BE33:BH33)) -> 27371.471 | BJ33: =IF(BJ13=1,Actuals!BW35,AVERAGE(BF33:BI33)) -> 27371.471 | BK33: =IF(BK13=1,Actuals!BX35,AVERAGE(BG33:BJ33)) -> 27371.471 | BL33: =IF(BL13=1,Actuals!BY35,AVERAGE(BH33:BK33)) -> 27371.471 | BM33: =IF(BM13=1,Actuals!BZ35,AVERAGE(BI33:BL33)) -> 27371.471 | BN33: =IF(BN13=1,Actuals!CA35,AVERAGE(BJ33:BM33)) -> 27371.471 | BO33: =IF(BO13=1,Actuals!CB35,AVERAGE(BK33:BN33)) -> 27371.471 | BP33: =IF(BP13=1,Actuals!CC35,AVERAGE(BL33:BO33)) -> 27371.471 | BQ33: =IF(BQ13=1,Actuals!CD35,AVERAGE(BM33:BP33)) -> 27371.471 | ... BT33: =IF(BT13=1,Actuals!CG35,AVERAGE(BP33:BS33)) -> 27371.471
B35: Churn metrics
B36: Customers Available to Renew | F36: # | G36: =SUMIFS($M36:$BT36,$M$15:$BT$15,G$15) -> 395 | H36: =SUMIFS($M36:$BT36,$M$15:$BT$15,H$15) -> 324 | I36: =SUMIFS($M36:$BT36,$M$15:$BT$15,I$15) -> 240 | J36: =SUMIFS($M36:$BT36,$M$15:$BT$15,J$15) -> 228 | K36: =SUMIFS($M36:$BT36,$M$15:$BT$15,K$15) -> 228 | M36: ='Customer Control'!L37 -> 32 | N36: ='Customer Control'!M37 -> 41 | O36: ='Customer Control'!N37 -> 42 | P36: ='Customer Control'!O37 -> 27 | Q36: ='Customer Control'!P37 -> 35 | R36: ='Customer Control'!Q37 -> 34 | S36: ='Customer Control'!R37 -> 39 | T36: ='Customer Control'!S37 -> 33 | ... BT36: ='Customer Control'!BS37 -> 19
B37: ARR Available to Renew | F37: $ | G37: =SUMIFS($M37:$BT37,$M$15:$BT$15,G$15) -> 9915102.5 | H37: =SUMIFS($M37:$BT37,$M$15:$BT$15,H$15) -> 7590986.5 | I37: =SUMIFS($M37:$BT37,$M$15:$BT$15,I$15) -> 5764112.4 | J37: =SUMIFS($M37:$BT37,$M$15:$BT$15,J$15) -> 6240682.6 | K37: =SUMIFS($M37:$BT37,$M$15:$BT$15,K$15) -> 6240695.3 | M37: =if(M$13=1,Actuals!N72,A19) -> 760857.5 | N37: =if(N$13=1,Actuals!O72,B19) -> 738900 | O37: =if(O$13=1,Actuals!P72,C19) -> 993687.5 | P37: =if(P$13=1,Actuals!Q72,D19) -> 852650 | Q37: =if(Q$13=1,Actuals!R72,E19) -> 635907.5 | R37: =if(R$13=1,Actuals!S72,F19) -> 994452.5 | S37: =if(S$13=1,Actuals!T72,G19) -> 1073757.5 | T37: =if(T$13=1,Actuals!U72,H19) -> 950895 | ... BT37: =if(BT$13=1,Actuals!BU72,BH19) -> 520057.94
B38: % Customer Churn | F38: % | G38: =iferror(AVERAGEIFS($M38:$BT38,$M$15:$BT$15,G$15),0) -> 0.25612251 | H38: =iferror(AVERAGEIFS($M38:$BT38,$M$15:$BT$15,H$15),0) -> 0.28838415 | I38: =iferror(AVERAGEIFS($M38:$BT38,$M$15:$BT$15,I$15),0) -> 0.28724948 | J38: =iferror(AVERAGEIFS($M38:$BT38,$M$15:$BT$15,J$15),0) -> 0.28685119 | K38: =iferror(AVERAGEIFS($M38:$BT38,$M$15:$BT$15,K$15),0) -> 0.28686375 | M38: ='Customer Control'!L38 -> 0.21875 | N38: ='Customer Control'!M38 -> 0.26829268 | O38: ='Customer Control'!N38 -> 0.26190476 | P38: ='Customer Control'!O38 -> 0.25925926 | Q38: ='Customer Control'!P38 -> 0.14285714 | R38: ='Customer Control'!Q38 -> 0.23529412 | S38: ='Customer Control'!R38 -> 0.15384615 | T38: ='Customer Control'!S38 -> 0.36363636 | ... BT38: ='Customer Control'!BS38 -> 0.28662804
B39: % ARR Churn | F39: % | G39: =iferror(AVERAGEIFS($M39:$BT39,$M$15:$BT$15,G$15),0) -> 0.25513059 | H39: =iferror(AVERAGEIFS($M39:$BT39,$M$15:$BT$15,H$15),0) -> 0.32341092 | I39: =iferror(AVERAGEIFS($M39:$BT39,$M$15:$BT$15,I$15),0) -> 0.33045508 | J39: =iferror(AVERAGEIFS($M39:$BT39,$M$15:$BT$15,J$15),0) -> 0.28685177 | K39: =iferror(AVERAGEIFS($M39:$BT39,$M$15:$BT$15,K$15),0) -> 0.28686375 | M39: =-M21/M37 -> 0.35585113 | N39: =-N21/N37 -> 0.16931114 | O39: =-O21/O37 -> 0.25095918 | P39: =-P21/P37 -> 0.31069255 | Q39: =-Q21/Q37 -> 0.24351026 | R39: =-R21/R37 -> 0.19023533 | S39: =-S21/S37 -> 0.12164385 | T39: =-T21/T37 -> 0.24128532 | ... BT39: =-BT21/BT37 -> 0.28662804
B41: Customer Retention | F41: % | G41: =(G36+G29)/G36 -> 0.74683544 | H41: =(H36+H29)/H36 -> 0.71186958 | I41: =(I36+I29)/I36 -> 0.71240572 | J41: =(J36+J29)/J36 -> 0.71314881 | K41: =(K36+K29)/K36 -> 0.71313625 | M41: =(M36+M29)/M36 -> 0.78125 | N41: =(N36+N29)/N36 -> 0.73170732 | O41: =(O36+O29)/O36 -> 0.73809524 | P41: =(P36+P29)/P36 -> 0.74074074 | Q41: =(Q36+Q29)/Q36 -> 0.85714286 | R41: =(R36+R29)/R36 -> 0.76470588 | S41: =(S36+S29)/S36 -> 0.84615385 | T41: =(T36+T29)/T36 -> 0.63636364 | ... BT41: =(BT36+BT29)/BT36 -> 0.71337196
B42: Gross Dollar Retention (GRR) | F42: % | G42: =Actuals!H74 -> 0.7366 | H42: =Actuals!I74 -> 0.7465 | I42: 0.8729 | J42: 0.89 | K42: 0.9 | M42: =Actuals!N74 -> 0.77416089 | N42: =Actuals!O74 -> 0.71439002 | O42: =Actuals!P74 -> 0.6465856 | P42: =Actuals!Q74 -> 0.72688936 | Q42: =Actuals!R74 -> 0.63821734 | R42: =Actuals!S74 -> 0.86334371 | S42: =Actuals!T74 -> 0.7727358 | T42: =Actuals!U74 -> 0.67358338 | ... AD42: =Actuals!AE74 -> 0.76515322 | AE42: 0.77986378 | AF42: 0.84236257 | AG42: 0.92487303 | AH42: 0.82939275 | AI42: 0.9791076 | AJ42: 0.96 | AK42: 0.83393937 | AL42: 0.873746 | AM42: 0.91 | AN42: 0.87297428 | AO42: 0.76557584 | AP42: 0.83771781 | AQ42: 0.88674301 | AR42: 0.88559028 | AS42: 0.88803397 | AT42: 0.89030993 | AU42: 0.88868364 | AV42: 0.89169824 | AW42: 0.89154911 | AX42: 0.88905633 | AY42: 0.88805567 | AZ42: 0.88850517 | BA42: 0.887865 | BB42: 0.88884184 | BC42: 0.89003246 | BD42: 0.89025082 | BE42: 0.88982747 | BF42: 0.88978342 | BG42: 0.88900029 | BH42: 0.88845952 | BI42: 0.88865839 | BJ42: 0.88910044 | BK42: 0.88936629 | BL42: 0.88974748 | BM42: 0.88977758 | BN42: 0.88946366 | BO42: 0.88914592 | BP42: 0.88900085 | BQ42: 0.88891727 | BR42: 0.88906628 | BS42: 0.88932982 | BT42: 0.88949106
B43: Net Dollar Retention (NRR) | F43: % | G43: =(G37+G21+G20+G19)/G37 -> 1.5208282 | H43: =(H37+H21+H20+H19)/H37 -> 1.7663209 | I43: 1.2 | J43: 1.15 | K43: 1.21 | M43: =Actuals!N75 -> 1.1029474 | N43: =Actuals!O75 -> 1.1537521 | O43: =Actuals!P75 -> 1.2498159 | P43: =Actuals!Q75 -> 1.0214469 | Q43: =Actuals!R75 -> 1.0383119 | R43: =Actuals!S75 -> 1.0357644 | S43: =Actuals!T75 -> 1.1883622 | T43: =Actuals!U75 -> 1.0136102 | ... AD43: =Actuals!AE75 -> 1.1427854 | AE43: 1.0877634 | AF43: 1.2681977 | AG43: 1.33 | AH43: 1.1469548 | AI43: 1.34 | AJ43: 1.35 | AK43: 1.36 | AL43: 1.2956552 | AM43: 1.33 | AN43: 1.37 | AO43: 1.2041079 | AP43: 1.19 | AQ43: 1.07 | AR43: 1.11 | AS43: 1.09 | AT43: 1.08 | AU43: 1.15 | AV43: 1.13 | AW43: 1.17 | AX43: 1.195 | AY43: 1.06 | AZ43: 1.245 | BA43: 1.1 | BB43: 1.13 | BC43: 1.12 | BD43: 1.345 | BE43: 1.03 | BF43: 1.19 | BG43: 1.18 | BH43: 1.045 | BI43: 1.07 | BJ43: 1.095 | BK43: 1.12 | BL43: 1.145 | BM43: 1.17 | BN43: 1.195 | BO43: 1.22 | BP43: 1.245 | BQ43: 1.27 | BR43: 1.295 | BS43: 1.32 | BT43: 1.345
B45: SaaS Metrics
B46: Average Lifetime (in years) | F46: # | G46: =iferror(1/G38,0) -> 3.9043816 | H46: =iferror(1/H38,0) -> 3.4675969 | I46: =iferror(1/I38,0) -> 3.4812944 | J46: =iferror(1/J38,0) -> 3.4861282 | K46: =iferror(1/K38,0) -> 3.4859755 | M46: =if(M13=1,Actuals!N77, 1/M38) -> 4.5714286 | N46: =if(N13=1,Actuals!O77, 1/N38) -> 3.7272727 | O46: =if(O13=1,Actuals!P77, 1/O38) -> 3.8181818 | P46: =if(P13=1,Actuals!Q77, 1/P38) -> 3.8571429 | Q46: =if(Q13=1,Actuals!R77, 1/Q38) -> 7 | R46: =if(R13=1,Actuals!S77, 1/R38) -> 4.25 | S46: =if(S13=1,Actuals!T77, 1/S38) -> 6.5 | T46: =if(T13=1,Actuals!U77, 1/T38) -> 2.75 | ... BT46: =if(BT13=1,Actuals!BU77, 1/BT38) -> 3.4888422
B47: LTV | F47: $ | G47: =SUMIFS($M47:$BT47,$M$15:$BT$15,G$15) -> 1021595.8 | H47: =SUMIFS($M47:$BT47,$M$15:$BT$15,H$15) -> 1010950.2 | I47: =SUMIFS($M47:$BT47,$M$15:$BT$15,I$15) -> 1140714.3 | J47: =SUMIFS($M47:$BT47,$M$15:$BT$15,J$15) -> 1145057.5 | K47: =SUMIFS($M47:$BT47,$M$15:$BT$15,K$15) -> 1144996.7 | M47: =if(M13=1,Actuals!N78,M46*A33) -> 88007.096 | N47: =if(N13=1,Actuals!O78,N46*B33) -> 72915.966 | O47: =if(O13=1,Actuals!P78,O46*C33) -> 75963.473 | P47: =if(P13=1,Actuals!Q78,P46*D33) -> 77259.912 | Q47: =if(Q13=1,Actuals!R78,Q46*E33) -> 140295.15 | R47: =if(R13=1,Actuals!S78,R46*F33) -> 85614.731 | S47: =if(S13=1,Actuals!T78,S46*G33) -> 132827 | T47: =if(T13=1,Actuals!U78,T46*H33) -> 56995.221 | ... BT47: =if(BT13=1,Actuals!BU78,BT46*BH33) -> 95494.743
B48: CAC | F48: $ | G48: =SUMIFS($M48:$BT48,$M$15:$BT$15,G$15) -> 359046.22 | H48: =SUMIFS($M48:$BT48,$M$15:$BT$15,H$15) -> 369780.86 | I48: =SUMIFS($M48:$BT48,$M$15:$BT$15,I$15) -> 382869.97 | J48: =SUMIFS($M48:$BT48,$M$15:$BT$15,J$15) -> 390289.41 | K48: =SUMIFS($M48:$BT48,$M$15:$BT$15,K$15) -> 394998.73 | M48: =if(M13=1,Actuals!N79,'P&L'!A28*1000) -> 37500 | N48: =if(N13=1,Actuals!O79,'P&L'!B28*1000) -> 28571.429 | O48: =if(O13=1,Actuals!P79,'P&L'!C28*1000) -> 26086.957 | P48: =if(P13=1,Actuals!Q79,'P&L'!D28*1000) -> 31578.947 | Q48: =if(Q13=1,Actuals!R79,'P&L'!E28*1000) -> 33333.333 | R48: =if(R13=1,Actuals!S79,'P&L'!F28*1000) -> 21428.571 | S48: =if(S13=1,Actuals!T79,'P&L'!G28*1000) -> 24000 | T48: =if(T13=1,Actuals!U79,'P&L'!H28*1000) -> 26086.957 | ... AD48: =if(AD13=1,Actuals!AE79,'P&L'!R28*1000) -> 26086.957 | AE48: =if(AE13=1,Actuals!AF79,'P&L'!S28*1000/AE28) -> 31578.947 | AF48: =if(AF13=1,Actuals!AG79,'P&L'!T28*1000/AF28) -> 31578.947 | AG48: =if(AG13=1,Actuals!AH79,'P&L'!U28*1000/AG28) -> 31578.947 | AH48: =if(AH13=1,Actuals!AI79,'P&L'!V28*1000/AH28) -> 31578.947 | AI48: =if(AI13=1,Actuals!AJ79,'P&L'!W28*1000/AI28) -> 31578.947 | AJ48: =if(AJ13=1,Actuals!AK79,'P&L'!X28*1000/AJ28) -> 31578.947 | AK48: =if(AK13=1,Actuals!AL79,'P&L'!Y28*1000/AK28) -> 31578.947 | AL48: =if(AL13=1,Actuals!AM79,'P&L'!Z28*1000/AL28) -> 31578.947 | ... BT48: =if(BT13=1,Actuals!BU79,'P&L'!BH28*1000/BT28) -> 33097.812
B49: LTV:CAC | F49: # | G49: =G47/G48 -> 2.8453044 | H49: =H47/H48 -> 2.7339169 | I49: =I47/I48 -> 2.9793779 | J49: =J47/J48 -> 2.9338677 | K49: =K47/K48 -> 2.8987353 | M49: =M47/M48 -> 2.3468559 | N49: =N47/N48 -> 2.5520588 | O49: =O47/O48 -> 2.9119331 | P49: =P47/P48 -> 2.4465639 | Q49: =Q47/Q48 -> 4.2088544 | R49: =R47/R48 -> 3.9953541 | S49: =S47/S48 -> 5.5344584 | T49: =T47/T48 -> 2.1848168 | ... BT49: =BT47/BT48 -> 2.8852282
B50: Rule of 40 | F50: % | G50: =IFERROR('P&L'!G33+'P&L'!G20,0) -> 0 | H50: =IFERROR('P&L'!H33+'P&L'!H20,0) -> 0.42043741 | I50: =IFERROR('P&L'!I33+'P&L'!I20,0) -> 0.53908644 | J50: =IFERROR('P&L'!J33+'P&L'!J20,0) -> 0.58552753 | K50: =IFERROR('P&L'!K33+'P&L'!K20,0) -> 0.60947923 | M50: =IFERROR('P&L'!M33+'P&L'!M20,0) -> 0 | N50: =IFERROR('P&L'!N33+'P&L'!N20,0) -> -0.34577212 | O50: =IFERROR('P&L'!O33+'P&L'!O20,0) -> -0.29539151 | P50: =IFERROR('P&L'!P33+'P&L'!P20,0) -> -0.27375264 | Q50: =IFERROR('P&L'!Q33+'P&L'!Q20,0) -> -0.25232136 | R50: =IFERROR('P&L'!R33+'P&L'!R20,0) -> -0.19291897 | S50: =IFERROR('P&L'!S33+'P&L'!S20,0) -> -0.13906992 | T50: =IFERROR('P&L'!T33+'P&L'!T20,0) -> -0.12246717 | ... BT50: =IFERROR('P&L'!BT33+'P&L'!BT20,0) -> 0.44505648

Sheet P&L
B2: Income statement (P&L) SaaS Financial Model
G5: =IF(G13=1,"Actual","Forecast") -> Actual | H5: =IF(H13=1,"Actual","Forecast") -> Actual | I5: =IF(I13=1,"Actual","Forecast") -> Forecast | J5: =IF(J13=1,"Actual","Forecast") -> Forecast | K5: =IF(K13=1,"Actual","Forecast") -> Forecast | M5: =IF(M13=1,"Actual","Forecast") -> Actual | N5: =IF(N13=1,"Actual","Forecast") -> Actual | O5: =IF(O13=1,"Actual","Forecast") -> Actual | P5: =IF(P13=1,"Actual","Forecast") -> Actual | Q5: =IF(Q13=1,"Actual","Forecast") -> Actual | R5: =IF(R13=1,"Actual","Forecast") -> Actual | S5: =IF(S13=1,"Actual","Forecast") -> Actual | T5: =IF(T13=1,"Actual","Forecast") -> Actual | ... BT5: =IF(BT13=1,"Actual","Forecast") -> Forecast
G6: =G7 -> 44562 | H6: =H7 -> 44927 | I6: =I7 -> 45292 | J6: =J7 -> 45658 | K6: =K7 -> 46023 | M6: =M7 -> 44562 | N6: =N7 -> 44593 | O6: =O7 -> 44621 | P6: =P7 -> 44652 | Q6: =Q7 -> 44682 | R6: =R7 -> 44713 | S6: =S7 -> 44743 | T6: =T7 -> 44774 | ... BT6: =BT7 -> 46357
F7: Start Date | G7: ='Key Assumptions'!D13 -> 44562 | H7: =G8+1 -> 44927 | I7: =H8+1 -> 45292 | J7: =I8+1 -> 45658 | K7: =J8+1 -> 46023 | M7: ='Key Assumptions'!D13 -> 44562 | N7: =M8+1 -> 44593 | O7: =N8+1 -> 44621 | P7: =O8+1 -> 44652 | Q7: =P8+1 -> 44682 | R7: =Q8+1 -> 44713 | S7: =R8+1 -> 44743 | T7: =S8+1 -> 44774 | U7: =T8+1 -> 44805 | ... BT7: =BS8+1 -> 46357
F8: End Date | G8: =EOMONTH(G7,11) -> 44926 | H8: =EOMONTH(H7,11) -> 45291 | I8: =EOMONTH(I7,11) -> 45657 | J8: =EOMONTH(J7,11) -> 46022 | K8: =EOMONTH(K7,11) -> 46387 | M8: =EOMONTH(M7,0) -> 44592 | N8: =EOMONTH(N7,0) -> 44620 | O8: =EOMONTH(O7,0) -> 44651 | P8: =EOMONTH(P7,0) -> 44681 | Q8: =EOMONTH(Q7,0) -> 44712 | R8: =EOMONTH(R7,0) -> 44742 | S8: =EOMONTH(S7,0) -> 44773 | T8: =EOMONTH(T7,0) -> 44804 | ... BT8: =EOMONTH(BT7,0) -> 46387
F9: Timeline | G9: =IF(G8-G7>35,"Annual","Monthly") -> Annual | H9: =IF(H8-H7>35,"Annual","Monthly") -> Annual | I9: =IF(I8-I7>35,"Annual","Monthly") -> Annual | J9: =IF(J8-J7>35,"Annual","Monthly") -> Annual | K9: =IF(K8-K7>35,"Annual","Monthly") -> Annual | M9: =IF(M8-M7>35,"Annual","Monthly") -> Monthly | N9: =IF(N8-N7>35,"Annual","Monthly") -> Monthly | O9: =IF(O8-O7>35,"Annual","Monthly") -> Monthly | P9: =IF(P8-P7>35,"Annual","Monthly") -> Monthly | Q9: =IF(Q8-Q7>35,"Annual","Monthly") -> Monthly | R9: =IF(R8-R7>35,"Annual","Monthly") -> Monthly | S9: =IF(S8-S7>35,"Annual","Monthly") -> Monthly | T9: =IF(T8-T7>35,"Annual","Monthly") -> Monthly | ... BT9: =IF(BT8-BT7>35,"Annual","Monthly") -> Monthly
F10: Year | G10: =YEAR(G7) -> 2022 | H10: =YEAR(H7) -> 2023 | I10: =YEAR(I7) -> 2024 | J10: =YEAR(J7) -> 2025 | K10: =YEAR(K7) -> 2026 | M10: =YEAR(M7) -> 2022 | N10: =YEAR(N7) -> 2022 | O10: =YEAR(O7) -> 2022 | P10: =YEAR(P7) -> 2022 | Q10: =YEAR(Q7) -> 2022 | R10: =YEAR(R7) -> 2022 | S10: =YEAR(S7) -> 2022 | T10: =YEAR(T7) -> 2022 | ... BT10: =YEAR(BT7) -> 2026
F12: Flag
